Workbook

Sheet CUSTOS_nominal
A1: key | B1: UF | C1: Estado | D1: Municipio | E1: IBGE | F1: tipo_coluna | G1: 2015-01 | H1: 2015-02 | I1: 2015-03 | J1: 2015-04 | K1: 2015-05 | L1: 2015-06 | M1: 2015-07 | N1: 2015-08 | O1: 2015-09 | P1: 2015-10 | Q1: 2015-11 | R1: 2015-12 | S1: 2016-01 | T1: 2016-02 | U1: 2016-03 | V1: 2016-04 | W1: 2016-05 | X1: 2016-06 | Y1: 2016-07 | Z1: 2016-08 | AA1: 2016-09 | AB1: 2016-10 | AC1: 2016-11 | AD1: 2016-12 | AE1: 2017-01 | AF1: 2017-02 | AG1: 2017-03 | AH1: 2017-04 | AI1: 2017-05 | AJ1: 2017-06 | AK1: 2017-07 | AL1: 2017-08 | AM1: 2017-09 | AN1: 2017-10 | AO1: 2017-11 | AP1: 2017-12 | AQ1: 2018-01 | AR1: 2018-02 | AS1: 2018-03 | AT1: 2018-04 | AU1: 2018-05 | AV1: 2018-06 | AW1: 2018-07 | AX1: 2018-08 | AY1: 2018-09 | AZ1: 2018-10 | BA1: 2018-11 | BB1: 2018-12 | BC1: 2019-01 | BD1: 2019-02 | BE1: 2019-03 | BF1: 2019-04 | BG1: 2019-05 | BH1: 2019-06 | BI1: 2019-07 | BJ1: 2019-08 | BK1: 2019-09 | BL1: 2019-10 | BM1: 2019-11 | BN1: 2019-12
A2: IBGE:2700102 | B2: AL | C2: Alagoas | D2: AGUA BRANCA | E2: 2700102 | F2: MEDIO | G2: 80679.85 | H2: 78209.08 | I2: 78070.85 | J2: 55241.54 | K2: 66738.79 | L2: 74095.39 | M2: 71289.56 | N2: 73931.32 | O2: 73836.82 | P2: 68697.06 | Q2: 49648.1 | R2: 48460.43 | S2: 47178.95 | T2: 49093.17 | U2: 49326.09 | V2: 52187.58 | W2: 62248.33 | X2: 55418.34 | Y2: 54688.93 | Z2: 58623.79 | AA2: 57285.7 | AB2: 71900.07 | AE2: 68592.78 | AF2: 64659.14 | AG2: 112895.59 | AH2: 65361.05 | AI2: 70861.58 | AJ2: 32166.96 | AK2: 0 | AL2: 8326.27 | AM2: 36321.44 | AN2: 40508.02 | AO2: 41476.87 | AQ2: 64447.71 | AR2: 53640.46 | AS2: 60514.55 | AT2: 64844.94 | AU2: 63215.74 | AV2: 64636.08 | AW2: 67714.78 | AX2: 22138.37 | AY2: 55493.68 | AZ2: 63471.91 | BA2: 67159.66 | BB2: 59107.8 | BC2: 67131.29 | BD2: 59095.71 | BE2: 59277.85 | BF2: 64194.34 | BG2: 62775.04 | BH2: 55305.11 | BI2: 53259.71 | BK2: 57549.02 | BL2: 63129.55 | BM2: 58590.35 | BN2: 60434.82
A3: IBGE:2700706 | B3: AL | C3: Alagoas | D3: BATALHA | E3: 2700706 | F3: MEDIO | G3: 61760.38 | H3: 60953.96 | I3: 60929.71 | J3: 43058.62 | K3: 51734.22 | L3: 37642.79 | M3: 44628.34 | N3: 59561.69 | O3: 61629.04 | P3: 58904.53 | Q3: 59164.12 | R3: 66339.49 | S3: 64488.14 | T3: 48932.43 | U3: 59120.06 | V3: 64768.39 | W3: 74791.18 | X3: 61391.83 | Y3: 69281.98 | Z3: 73861.59 | AA3: 71521.91 | AB3: 87249.39 | AE3: 69048.72 | AF3: 80620.55 | AG3: 124592.26 | AH3: 82217.13 | AI3: 71213.51 | AJ3: 44348.53 | AK3: 39676.76 | AL3: 43152.67 | AM3: 42433.9 | AN3: 44126.02 | AO3: 45771.67 | AQ3: 49392.78 | AR3: 41812.24 | AS3: 44810.97 | AT3: 46061.49 | AU3: 44655.05 | AV3: 43838.29 | AW3: 64770.07 | AX3: 26139.71 | AY3: 50497.6 | AZ3: 58458.28 | BA3: 58484.79 | BB3: 58861.52 | BC3: 46010.27 | BD3: 37215.99 | BE3: 42637.97 | BF3: 45726.17 | BG3: 46652.22 | BH3: 46112.92 | BI3: 45827.42 | BJ3: 29068.24 | BK3: 47304.93 | BL3: 46507.97 | BM3: 47424.72 | BN3: 46841.43
A4: IBGE:2501906 | B4: AL | C4: Alagoas | D4: BELEM | E4: 2501906 | F4: MEDIO | G4: 32070.72 | H4: 30597.13 | I4: 30572.88 | J4: 26443.69 | K4: 16110.1 | L4: 30808.14 | M4: 29454.48 | N4: 30377.35 | O4: 32107.4 | P4: 29386.89 | Q4: 36949.79 | R4: 38791.6 | S4: 37510.12 | T4: 31410.84 | U4: 26524.44 | V4: 31088.58 | W4: 41500.08 | X4: 30681.47 | Y4: 35073.61 | Z4: 39510.25 | AA4: 40197.28 | AB4: 55793.77 | AE4: 25634.39 | AF4: 29316.895 | AG4: 50323.135 | AH4: 29413.65 | AI4: 28352.605 | AJ4: 9912.985 | AK4: 9584.735 | AL4: 13606.535 | AM4: 21637.28 | AN4: 20562.79
A5: IBGE:2700904 | B5: AL | C5: Alagoas | D5: BELO MONTE | E5: 2700904 | F5: MEDIO | G5: 36030.23 | H5: 35738.93 | I5: 39714.68 | J5: 31584.68 | K5: 31584.68 | L5: 17988.8 | M5: 29447.34 | N5: 35904.1 | O5: 25637.85 | P5: 22913.34 | Q5: 41775.76 | R5: 46237.39 | S5: 69439.85 | T5: 69507.11 | U5: 65033.63 | V5: 69597.77 | W5: 79263.98 | X5: 64053.6 | Y5: 70207.9 | Z5: 76545.39 | AA5: 77232.42 | AB5: 91482.03 | AE5: 78583.11 | AF5: 80732.61 | AG5: 125732.08 | AH5: 82413.47 | AI5: 52258.58 | AJ5: 28039.38 | AK5: 15058.04 | AL5: 9981.75 | AM5: 35808.12 | AN5: 35691.26 | AO5: 36574.37 | AQ5: 38825.82 | AR5: 33617.45 | AS5: 36699.82 | AT5: 35627.09 | AU5: 36628.54 | AV5: 35210.54 | AW5: 64219.61 | AX5: 33231.64 | AY5: 53246.62 | AZ5: 67353.91 | BA5: 66555.7 | BB5: 65539.43 | BC5: 35209.65 | BD5: 31691.49 | BE5: 33632.27 | BF5: 40562.32 | BG5: 37367.51 | BH5: 36209.21 | BI5: 40742.61 | BJ5: 24413.34 | BK5: 38572.65 | BL5: 72281.36 | BM5: 68487.57 | BN5: 67917.2
A6: IBGE:2701209 | B6: AL | C6: Alagoas | D6: CACIMBINHAS | E6: 2701209 | F6: MEDIO | G6: 0 | H6: 0 | I6: 0 | J6: 0 | K6: 0 | L6: 0 | M6: 0 | N6: 0 | O6: 130832.08 | P6: 166964.19 | Q6: 102879.4 | R6: 130843.29 | S6: 129561.81 | T6: 132666.76 | U6: 131472.22 | V6: 136848.98 | W6: 150503.68 | X6: 137135.51 | Y6: 143397.36 | Z6: 145794.53 | AA6: 145946.27 | AB6: 161026.26 | AE6: 149179.32 | AF6: 153617.16 | AG6: 197703.53 | AH6: 155324.91 | AI6: 165626.2 | AJ6: 25295.75 | AK6: 7764.23 | AL6: 76002.34 | AM6: 143140.18 | AN6: 151059.19 | AO6: 130005.7 | AQ6: 145887.46 | AR6: 126906.38 | AS6: 140196.1 | AT6: 134586.88 | AU6: 128995.69 | AV6: 135497.81 | AW6: 144218.87 | AX6: 55977.45 | AY6: 79330.76 | AZ6: 90448.34 | BA6: 92920.93 | BB6: 83106.51 | BC6: 87114.28 | BD6: 79095.15 | BE6: 78734.94 | BF6: 96752.36 | BG6: 84427.87 | BH6: 71950.57 | BI6: 57420.98 | BJ6: 53545.68 | BK6: 97315.42 | BL6: 119975.97 | BM6: 108420.93 | BN6: 109486.35
A7: IBGE:2701605 | B7: AL | C7: Alagoas | D7: CANAPI | E7: 2701605 | F7: MEDIO | G7: 88305.51 | H7: 71775.01 | I7: 82240.23 | J7: 80809.03 | K7: 82941.85 | L7: 88304.8 | M7: 87316.33 | N7: 88836.87 | O7: 90596.32 | P7: 74113.5 | Q7: 53601.71 | R7: 100922.89 | S7: 96869.17 | T7: 35333.55 | U7: 92465.73 | V7: 98113.17 | W7: 106908.07 | X7: 96089.46 | Y7: 91432.35 | Z7: 100252.8 | AA7: 98506.29 | AB7: 120166.73 | AE7: 157361.29 | AF7: 167091.63 | AG7: 207681.31 | AH7: 164726.99 | AI7: 160618.92 | AJ7: 72589.72 | AK7: 113503.48 | AL7: 11450.14 | AM7: 134855.42 | AN7: 134359.52 | AO7: 131828.47 | AQ7: 136775.29 | AR7: 124196.53 | AS7: 129279.28 | AT7: 137449.58 | AU7: 135005.83 | AV7: 138922.26 | AW7: 153535.95 | AX7: 109739.63 | AY7: 132940.51 | AZ7: 159291.56 | BA7: 154531.05 | BB7: 124319.32 | BC7: 137066.27 | BD7: 143833.31 | BE7: 151328.8 | BF7: 142156.91 | BG7: 171954.33 | BH7: 152877.12 | BI7: 180975.33 | BJ7: 97881.78 | BK7: 171629.87 | BL7: 190712.71 | BM7: 182773.58 | BN7: 190927.71
A8: IBGE:2701803 | B8: AL | C8: Alagoas | D8: CARNEIROS | E8: 2701803 | F8: MEDIO | G8: 32378.33 | H8: 31884.93 | I8: 35211.78 | J8: 31082.59 | K8: 28310.36 | L8: 34727.85 | M8: 33564.54 | N8: 32991.7 | O8: 36250.45 | P8: 33525.94 | Q8: 27884.34 | R8: 33399.48 | S8: 32118 | T8: 35213.61 | U8: 30327.21 | V8: 34891.35 | W8: 44060.79 | X8: 33515.38 | Y8: 37968.74 | Z8: 41896.71 | AA8: 41019.15 | AB8: 58180.23 | AE8: 45586.36 | AF8: 52796.71 | AG8: 94139.62 | AH8: 51042.12 | AI8: 51419.39 | AJ8: 12969.3 | AK8: 0 | AL8: 15790.85 | AM8: 25177.72 | AN8: 24611.01 | AO8: 26762.12 | AQ8: 28804.04 | AR8: 22729.6 | AS8: 25905.79 | AT8: 27963.81 | AU8: 25824.02 | AV8: 28175.85 | AW8: 31373 | AX8: 14341.7 | AY8: 24148.4 | AZ8: 30819.2 | BA8: 31077.65 | BB8: 27926.32 | BC8: 45342.92 | BD8: 37309.36 | BE8: 38552.93 | BF8: 47434.82 | BG8: 43854.3 | BH8: 44083.66 | BI8: 35009.48 | BJ8: 20437.65 | BK8: 40384.99 | BL8: 47119.56 | BM8: 42098.74 | BN8: 39076.97
A9: IBGE:2702009 | B9: AL | C9: Alagoas | D9: COITE DO NOIA | E9: 2702009 | F9: MEDIO | G9: 22475.43 | H9: 21841.03 | I9: 21605.38 | J9: 17687.59 | K9: 16301 | L9: 21919.88 | M9: 20735.42 | N9: 21150.05 | O9: 22909.5 | P9: 20184.99 | Q9: 27396.28 | R9: 29238.09 | S9: 27956.61 | T9: 29084.72 | U9: 24872.03 | V9: 29031.01 | W9: 39241.87 | X9: 28175.19 | Y9: 32815.4 | Z9: 36302.96 | AA9: 36476.7 | AB9: 52586.48 | AE9: 40261.64 | AF9: 47562.01 | AG9: 88904.92 | AH9: 45807.42 | AI9: 42527.23 | AJ9: 10161.17 | AK9: 6512.63 | AL9: 12049.12 | AM9: 19065.21 | AN9: 18892.78 | AO9: 18541.59 | AQ9: 19755.62 | AR9: 17098.8 | AS9: 18477.68 | AT9: 16660.63 | AU9: 17005.49 | AY9: 11656.29 | AZ9: 19917.33 | BA9: 15822.27 | BB9: 16678.13 | BC9: 21231.33 | BD9: 16193.83 | BE9: 18278.08 | BF9: 19177.02 | BG9: 20637.88 | BH9: 18954.5 | BK9: 19146.59 | BL9: 21856.58 | BM9: 18573.66 | BN9: 16402.08
A10: IBGE:2702355 | B10: AL | C10: Alagoas | D10: CRAIBAS | E10: 2702355 | F10: MEDIO | G10: 57068.84 | H10: 56458.88 | I10: 56046.88 | J10: 42698.41 | K10: 50907.49 | L10: 56635.49 | M10: 55281.83 | N10: 54966.08 | O10: 57305.98 | P10: 45520.97 | Q10: 43611.42 | R10: 45857.43 | S10: 44336.95 | T10: 47349.32 | U10: 42856.51 | V10: 47420.65 | W10: 56913.27 | X10: 46295.44 | Y10: 50923.13 | Z10: 55351.71 | AA10: 52783.24 | AB10: 72005.77 | AE10: 58019.31 | AF10: 63523.16 | AG10: 106094.08 | AH10: 63238.48 | AI10: 57331.12 | AJ10: 14561.09 | AK10: 7434.56 | AL10: 21979.5 | AM10: 36966.61 | AN10: 35957.39 | AO10: 35273.33 | AQ10: 37384.23 | AR10: 32155.48 | AS10: 33384.64 | AT10: 31831.73 | AU10: 32983.21 | AY10: 29224.87 | AZ10: 44124.6 | BA10: 38771.45 | BB10: 40305.72 | BC10: 44115.99 | BD10: 35403.55 | BE10: 39133.75 | BF10: 44462.65 | BG10: 43056.13 | BH10: 43146.29 | BI10: 35904.24 | BJ10: 12448.75 | BK10: 36310.18 | BL10: 45382.94 | BM10: 40073.47 | BN10: 35035.45
A11: IBGE:2702405 | B11: AL | C11: Alagoas | D11: DELMIRO GOUVEIA | E11: 2702405 | F11: MEDIO | G11: 24551.89 | H11: 29042.37 | I11: 30636.81 | J11: 26507.52 | K11: 23002.18 | L11: 31359.36 | M11: 29690.8 | N11: 27762.48 | O11: 31823.23 | P11: 18988.84 | Q11: 22016.85 | R11: 21953.18 | S11: 20671.66 | T11: 25621.38 | U11: 21206.38 | V11: 25770.52 | W11: 35774.6 | X11: 25093.69 | Y11: 29348.13 | Z11: 32973.39 | AA11: 33302.32 | AB11: 49256.91 | AE11: 36477.14 | AF11: 42664.99 | AG11: 83855.72 | AH11: 40758.22 | AI11: 39191.29 | AJ11: 12187.08 | AK11: 13653.53 | AL11: 12711.23 | AM11: 12352.39 | AN11: 12906.78 | AO11: 12218.59 | AQ11: 13809.86 | AR11: 11611.52 | AS11: 12503.05 | AT11: 10712.04 | AU11: 10785.67 | AV11: 10997.73 | AW11: 12477.71 | AX11: 7888.91 | AY11: 8140.31 | AZ11: 13724.52 | BA11: 14582.83 | BB11: 13145.57 | BC11: 13015.61 | BD11: 9532.13 | BE11: 10625.48 | BF11: 12648.07 | BG11: 12947.85 | BH11: 10771.13 | BI11: 14209.81 | BJ11: 10402.93 | BK11: 10466.65 | BL11: 13300.63 | BM11: 10546.47 | BN11: 9656.18
A12: IBGE:2702504 | B12: AL | C12: Alagoas | D12: DOIS RIACHOS | E12: 2702504 | F12: MEDIO | G12: 62697.09 | H12: 64089.8 | I12: 64065.55 | J12: 59936.36 | K12: 58754.14 | L12: 58101.42 | M12: 50861.52 | N12: 45879.32 | O12: 48813.55 | P12: 54123.94 | Q12: 108989.77 | R12: 62894.46 | S12: 62926.07 | T12: 59745.94 | U12: 63472.74 | V12: 69028.36 | W12: 80230.39 | X12: 64668.61 | Y12: 73803.92 | Z12: 77817.05 | AA12: 78504.08 | AB12: 93740.22 | AE12: 81752.49 | AF12: 87190.88 | AG12: 127304.87 | AH12: 86280.9 | AI12: 85343.35 | AJ12: 49003.45 | AK12: 35208.79 | AL12: 54365.71 | AM12: 53398.49 | AN12: 61315.14 | AO12: 55224.97 | AQ12: 61994.65 | AR12: 46291.01 | AS12: 56673.28 | AT12: 58733.45 | AU12: 57666.69 | AV12: 54539.21 | AW12: 55042.62 | AX12: 29788.26 | AY12: 48630.83 | AZ12: 60117.83 | BA12: 54283.28 | BB12: 56629.86 | BC12: 58695.16 | BD12: 49445.49 | BE12: 53571.93 | BF12: 62546.51 | BG12: 63495.17 | BH12: 63117.86 | BI12: 56730.98 | BJ12: 31692.16 | BK12: 63274.06 | BL12: 57207.48 | BM12: 58784.01 | BN12: 58952.92
A13: IBGE:2702553 | B13: AL | C13: Alagoas | D13: ESTRELA DE ALAGOAS | E13: 2702553 | F13: MEDIO | G13: 160980.61 | H13: 161237.86 | I13: 143687.49 | J13: 139558.03 | K13: 143946.18 | L13: 145792.84 | M13: 157743 | N13: 147110.44 | O13: 148244.69 | P13: 133359.35 | Q13: 138066.91 | R13: 15468.58 | S13: 114187.1 | T13: 122247.57 | U13: 133701.46 | V13: 137848.61 | W13: 147720.85 | X13: 136022.04 | Y13: 138865.94 | Z13: 142200.59 | AA13: 142136.89 | AB13: 154254.78 | AE13: 206796.16 | AF13: 204491.37 | AG13: 255901.83 | AH13: 212362.88 | AI13: 206318.85 | AJ13: 42250.54 | AK13: 0 | AL13: 88470.93 | AM13: 180662.78 | AN13: 172783.82 | AO13: 150748.45 | AQ13: 157085.33 | AR13: 137950.84 | AS13: 148169.39 | AT13: 156671.37 | AU13: 148538.64 | AV13: 150057.15 | AW13: 161988.39 | AX13: 110931.45 | AY13: 142147.52 | AZ13: 147259.75 | BA13: 151611.63 | BB13: 152188.84 | BC13: 159748.26 | BD13: 178947.82 | BE13: 187837.35 | BF13: 196773.16 | BG13: 211832.41 | BH13: 193631.2 | BI13: 120678.77 | BJ13: 114508.77 | BK13: 207994.13 | BL13: 214852.05 | BM13: 209658.91 | BN13: 211480.14
A14: IBGE:2702900 | B14: AL | C14: Alagoas | D14: GIRAU DO PONCIANO | E14: 2702900 | F14: MEDIO | G14: 0 | H14: 0 | I14: 0 | J14: 0 | K14: 0 | L14: 0 | M14: 0 | N14: 0 | O14: 0 | P14: 0 | Q14: 206567.33 | R14: 278383.63 | S14: 277807.41 | T14: 302148.88 | U14: 231446.17 | V14: 292561.59 | W14: 305663.43 | X14: 292110.51 | Y14: 289906.43 | Z14: 303960.99 | AA14: 303111.57 | AB14: 318262.99 | AE14: 220023.19 | AF14: 184363.45 | AG14: 264605.56 | AH14: 207285.07 | AI14: 161729.11 | AJ14: 26550.62 | AK14: 0 | AL14: 100982.08 | AM14: 177159.39 | AN14: 163710.27 | AO14: 154554.82 | AQ14: 167978.48 | AR14: 145911.07 | AS14: 150528.56 | AT14: 166955.33 | AU14: 163173.54 | AY14: 148312.43 | AZ14: 162915.1 | BA14: 166244.56 | BB14: 160734.32 | BC14: 174696.51 | BD14: 147354.03 | BE14: 152451.35 | BF14: 181418.97 | BG14: 181838.93 | BH14: 175451.85 | BI14: 176528.7 | BJ14: 102203.61 | BK14: 179691.9 | BL14: 178993.33 | BM14: 178293.87 | BN14: 180231.44
A15: IBGE:2703106 | B15: AL | C15: Alagoas | D15: IGACI | E15: 2703106 | F15: MEDIO | Q15: 134034.59 | R15: 179039.01 | S15: 177811.95 | T15: 119379.96 | U15: 126841.55 | V15: 151410.41 | W15: 160833.15 | X15: 148233.45 | Y15: 150968.94 | Z15: 159037.76 | AA15: 149957.13 | AB15: 174752.09 | AE15: 156968.42 | AF15: 161487.05 | AG15: 207439.01 | AH15: 161876.91 | AI15: 128346.34 | AJ15: 19119.37 | AK15: 0 | AL15: 63244.13 | AM15: 115251.79 | AN15: 120047.11 | AO15: 98428.29 | AQ15: 115447.87 | AR15: 109018.87 | AS15: 114815.94 | AT15: 118454.91 | AU15: 119155.2 | AY15: 112618.48 | AZ15: 118199.65 | BA15: 119626 | BB15: 120532.89 | BC15: 116862.59 | BD15: 105847.96 | BE15: 113467.95 | BF15: 125962.43 | BG15: 124233.27 | BH15: 123367.82 | BI15: 78668.37 | BJ15: 65769.58 | BK15: 117801.66 | BL15: 121023.25 | BM15: 119137.76 | BN15: 115142.49
A16: IBGE:2703304 | B16: AL | C16: Alagoas | D16: INHAPI | E16: 2703304 | F16: MEDIO | G16: 65684.65 | H16: 58605.84 | I16: 64470.59 | J16: 50908.05 | K16: 59528.94 | L16: 64605.52 | M16: 58997.89 | N16: 64349.25 | O16: 64855.59 | P16: 63120.15 | Q16: 41675.04 | R16: 50927.91 | S16: 49646.43 | T16: 48489.36 | U16: 44268.16 | V16: 48865.29 | W16: 60481.01 | X16: 49662.4 | Y16: 50785.68 | Z16: 55866.64 | AA16: 53775.18 | AB16: 73392.26 | AE16: 61175.82 | AF16: 68335.17 | AG16: 108724.07 | AH16: 65914.69 | AI16: 65197.6 | AJ16: 7598.74 | AK16: 30024.3 | AL16: 28678.59 | AM16: 31875.24 | AN16: 37713.5 | AO16: 51244.68 | AQ16: 55583.8 | AR16: 49931.16 | AS16: 51754.4 | AT16: 47534.15 | AU16: 45793.88 | AV16: 45094.69 | AW16: 53669.68 | AX16: 21423.07 | AY16: 44588.94 | AZ16: 46080.88 | BA16: 53250.1 | BB16: 49772.05 | BC16: 53916.54 | BD16: 46369.27 | BE16: 47094.24 | BF16: 54323.36 | BG16: 54648.34 | BH16: 43467.15 | BI16: 47884.11 | BK16: 49417.5 | BL16: 56170.66 | BM16: 50038.51 | BN16: 48879.94
A17: IBGE:2703403 | B17: AL | C17: Alagoas | D17: JACARE DOS HOMENS | E17: 2703403 | F17: MEDIO | G17: 18663.26 | H17: 17564.03 | I17: 16350.38 | J17: 12221.49 | K17: 12336.94 | L17: 18246.83 | M17: 16893.17 | N17: 17236.36 | O17: 18995.81 | P17: 16271.3 | Q17: 25148.7 | R17: 39914.57 | S17: 52594.22 | T17: 21637.09 | U17: 20471.2 | V17: 25253.82 | W17: 33368.83 | X17: 19764.04 | Y17: 21058.56 | Z17: 32766.67 | AA17: 33453.7 | AB17: 49050.19 | AE17: 37708.55 | AF17: 45237.54 | AG17: 85545.32 | AH17: 42447.82 | AI17: 38130.16 | AJ17: 9486.51 | AK17: 0 | AL17: 8632.86 | AM17: 14227.97 | AN17: 13811.52 | AO17: 14182.01 | AQ17: 15863.61 | AR17: 13222.46 | AS17: 14308.57 | AT17: 12835.89 | AU17: 12485.91 | AV17: 12692.54 | AW17: 13640.83 | AX17: 7239.35 | AY17: 8348.33 | AZ17: 12647.05 | BA17: 12514.07 | BB17: 12064.78 | BC17: 13213.61 | BD17: 10389.85 | BE17: 11608.96 | BF17: 13165.73 | BG17: 13638.65 | BH17: 11957.07 | BI17: 14254.59 | BJ17: 10236.31 | BK17: 12578.46 | BL17: 14600.96 | BM17: 11515.47 | BN17: 11347.72
A18: IBGE:2703700 | B18: AL | C18: Alagoas | D18: JARAMATAIA | E18: 2703700 | F18: MEDIO | G18: 50870.65 | H18: 57861.46 | I18: 57837.11 | J18: 53707.92 | K18: 51685.81 | L18: 57731.06 | M18: 56377.4 | N18: 58043.17 | O18: 58205.09 | P18: 27055.92 | Q18: 27381.39 | R18: 29223.2 | S18: 27941.72 | T18: 51466.63 | U18: 48198.77 | V18: 52762.91 | W18: 62472.94 | X18: 51264.09 | Y18: 55656.23 | Z18: 61125.4 | AA18: 61812.43 | AB18: 75546.64 | AE18: 64742.45 | AF18: 72387.72 | AG18: 114180.84 | AH18: 71083.34 | AI18: 65020.06 | AJ18: 43679.98 | AK18: 41719.54 | AL18: 38001.58 | AM18: 44181.83 | AN18: 43110.17 | AO18: 48139.22 | AQ18: 52668.68 | AR18: 43689 | AS18: 48231.28 | AT18: 41558.4 | AU18: 42515.39 | AV18: 46935.36 | AW18: 42647.2 | AX18: 18440.11 | AY18: 42511.04 | AZ18: 50630.04 | BA18: 47798.99 | BB18: 47636.07 | BC18: 52780.23 | BD18: 45245.25 | BE18: 50636.76 | BF18: 58686.97 | BG18: 58040.79 | BH18: 53510.33 | BI18: 65892.49 | BJ18: 41156.59 | BK18: 68763.72 | BL18: 65609.21 | BM18: 64142.73 | BN18: 63960.63
A19: IBGE:2704104 | B19: AL | C19: Alagoas | D19: LAGOA DA CANOA | E19: 2704104 | F19: MEDIO | G19: 40061.89 | H19: 42562.63 | I19: 42800.64 | J19: 38671.45 | K19: 36812.66 | L19: 42540.66 | M19: 41187 | N19: 42024.63 | O19: 43441.92 | P19: 24899.57 | Q19: 31832.48 | R19: 34764.69 | S19: 33483.21 | T19: 36115.02 | U19: 32078.86 | V19: 36769.23 | W19: 46243.66 | X19: 35249.6 | Y19: 38174.87 | Z19: 45201.77 | AA19: 45001.62 | AB19: 61210.11 | AE19: 64838 | AF19: 64612.8 | AG19: 113311.26 | AH19: 70213.76 | AI19: 67309.25 | AJ19: 13511.41 | AK19: 0 | AL19: 25562.07 | AM19: 45450.38 | AN19: 44966.58 | AO19: 20956.4 | AQ19: 28164.63 | AR19: 24089.23 | AS19: 25943.71 | AT19: 24700.36 | AU19: 25534.85 | AY19: 21528.79 | AZ19: 25527.99 | BA19: 26356.76 | BB19: 26600.37 | BC19: 30517.46 | BD19: 24076.77 | BE19: 27454.59 | BF19: 30231.68 | BG19: 31283.08 | BH19: 28146.35 | BI19: 34416.47 | BK19: 29260.43 | BL19: 33945.94 | BM19: 29631.91 | BN19: 28386.17
A20: IBGE:2704401 | B20: AL | C20: Alagoas | D20: MAJOR IZIDORO | E20: 2704401 | F20: MEDIO | G20: 56172.52 | H20: 83075.45 | I20: 92954.23 | J20: 70810.52 | K20: 75494.84 | L20: 82680.07 | M20: 81772.91 | N20: 69981.64 | O20: 78851.72 | P20: 53122.12 | Q20: 127481.66 | R20: 116198.2 | S20: 114916.72 | T20: 121206.04 | U20: 116830.08 | V20: 129227.65 | W20: 145932.24 | X20: 118913.67 | Y20: 125787.42 | Z20: 142264.89 | AA20: 137753.71 | AB20: 158406.17 | AE20: 149675.14 | AF20: 136380.18 | AG20: 196043.14 | AH20: 151750.12 | AI20: 138436.65 | AJ20: 28235.62 | AK20: 7687.85 | AL20: 59227.92 | AM20: 104044.66 | AN20: 88424.27 | AO20: 100577.77 | AQ20: 102039.13 | AR20: 100940.34 | AS20: 100694.97 | AT20: 109342.55 | AU20: 112410.06 | AV20: 106117.83 | AW20: 97632.91 | AX20: 45367.99 | AY20: 103414.73 | AZ20: 112935.12 | BA20: 111106.83 | BB20: 99584.41 | BC20: 107039.05 | BD20: 97748.24 | BE20: 103594.25 | BF20: 104045.63 | BG20: 116400.39 | BH20: 97747.93 | BI20: 110858.93 | BJ20: 65304.76 | BK20: 124722.44 | BL20: 167245.53 | BM20: 159625.85 | BN20: 161577.56
A21: IBGE:2704609 | B21: AL | C21: Alagoas | D21: MARAVILHA | E21: 2704609 | F21: MEDIO | G21: 90094.95 | H21: 84785.78 | I21: 84761.28 | J21: 82429.32 | K21: 81328.71 | L21: 88664.11 | M21: 93767.78 | N21: 74736.24 | O21: 97526.83 | P21: 67449.72 | Q21: 91118.9 | R21: 71167.75 | S21: 69886.27 | T21: 104896.88 | U21: 86031.95 | V21: 95674 | W21: 105972.41 | X21: 90185.5 | Y21: 98871.72 | Z21: 102839.23 | AA21: 107891.57 | AB21: 121322.46 | AE21: 116924.47 | AF21: 124648.18 | AG21: 166467.01 | AH21: 123369.51 | AI21: 119222.18 | AJ21: 94648.55 | AK21: 62128.38 | AL21: 44382.56 | AM21: 93896.27 | AN21: 91286.04 | AO21: 86591.92 | AQ21: 92547.4 | AR21: 78630.69 | AS21: 84758.93 | AT21: 88928.18 | AU21: 88761.18 | AV21: 86264.94 | AW21: 89248.74 | AX21: 79234.99 | AY21: 78544.49 | AZ21: 87899.28 | BA21: 80979.81 | BB21: 82680.11 | BC21: 92254.53 | BD21: 78003.27 | BE21: 82940.89 | BF21: 97206.12 | BG21: 96093.01 | BH21: 84648.35 | BI21: 105967.8 | BJ21: 61251.35 | BK21: 88450.22 | BL21: 94591.85 | BM21: 86042.65 | BN21: 86440.56
A22: IBGE:2705002 | B22: AL | C22: Alagoas | D22: MATA GRANDE | E22: 2705002 | F22: MEDIO | G22: 77792.79 | H22: 58795.73 | I22: 72575.61 | J22: 67944.46 | K22: 78266.05 | L22: 73756.03 | M22: 50296.83 | N22: 73624 | O22: 76792.88 | P22: 73852.17 | Q22: 26203.08 | R22: 72891.76 | S22: 71610.28 | T22: 75767.6 | U22: 71226.14 | V22: 75790.27 | W22: 85777.22 | X22: 74316.78 | Y22: 69698.73 | Z22: 77065.39 | AA22: 76054.75 | AB22: 90730.43 | AE22: 85132.08 | AF22: 95671.63 | AG22: 134935.23 | AH22: 91971.74 | AI22: 86138.1 | AJ22: 61398.17 | AK22: 64032.78 | AL22: 11587.54 | AM22: 68135.2 | AN22: 65763.42 | AO22: 62998.01 | AQ22: 80888.16 | AR22: 71785.95 | AS22: 73377.91 | AT22: 76308.38 | AU22: 77490.79 | AV22: 74731.97 | AW22: 81593.98 | AX22: 44103.8 | AY22: 69369.01 | AZ22: 92549.16 | BA22: 84535.6 | BB22: 86289.17 | BC22: 80320.48 | BD22: 76672.9 | BE22: 82425.29 | BF22: 91831.08 | BG22: 90024.03 | BH22: 68747.48 | BI22: 83825.57 | BJ22: 53111.32 | BK22: 78465.88 | BL22: 87837.1 | BM22: 82494.89 | BN22: 81757.51
A23: IBGE:2705309 | B23: AL | C23: Alagoas | D23: MINADOR DO NEGRAO | E23: 2705309 | F23: MEDIO | G23: 0 | H23: 0 | I23: 0 | J23: 0 | K23: 0 | L23: 0 | M23: 0 | N23: 0 | O23: 0 | P23: 0 | Q23: 66203.1 | R23: 68199.07 | S23: 66917.59 | T23: 58525.74 | U23: 50117.32 | V23: 65755.95 | W23: 82359.81 | X23: 71057.08 | Y23: 75933.34 | Z23: 72548.34 | AA23: 73353.76 | AB23: 86689.39 | AE23: 96027.36 | AF23: 94640.48 | AG23: 141084.05 | AH23: 96357.54 | AI23: 96474.97 | AJ23: 16588.81 | AK23: 7515.27 | AL23: 39817.7 | AM23: 64958.68 | AN23: 69233.17 | AO23: 59303.08 | AQ23: 60609.57 | AR23: 52946.29 | AS23: 57566.61 | AT23: 58375.23 | AU23: 45533.75 | AV23: 43783.33 | AW23: 60972.17 | AX23: 42921.6 | AY23: 51155.01 | AZ23: 58605.36 | BA23: 55950.01 | BB23: 53993.09 | BC23: 59871.93 | BD23: 48823.62 | BE23: 57107.21 | BF23: 61421.47 | BG23: 59989 | BH23: 50302.77 | BI23: 48398.54 | BK23: 56269.63 | BL23: 62971.99 | BM23: 58762.03 | BN23: 56519.58
A24: IBGE:2705408 | B24: AL | C24: Alagoas | D24: MONTEIROPOLIS | E24: 2705408 | F24: MEDIO | G24: 22189.17 | H24: 30197.4 | I24: 37331.25 | J24: 33522.76 | K24: 31390.98 | L24: 33515.02 | M24: 35209 | N24: 16560.51 | O24: 3434.4 | P24: 28789.75 | Q24: 22728.2 | R24: 34762.62 | S24: 33481.14 | T24: 27280.83 | U24: 28507.01 | V24: 33071.15 | W24: 42321.28 | X24: 35593.3 | Y24: 39453.72 | Z24: 46421.46 | AA24: 46926.21 | AB24: 62704.98 | AE24: 47523.39 | AF24: 51589.53 | AG24: 94952.71 | AH24: 50945.14 | AI24: 48623.28 | AJ24: 10330.75 | AK24: 0 | AL24: 17045.57 | AM24: 25367.05 | AN24: 26447.61 | AO24: 28201.22 | AQ24: 29477.59 | AR24: 25399.79 | AS24: 27285.35 | AT24: 26380.93 | AU24: 25946.91 | AV24: 23028.88 | AW24: 26893.81 | AX24: 12995.02 | AY24: 21658.8 | AZ24: 28233.96 | BA24: 28547.42 | BB24: 19509.17 | BC24: 23663.88 | BD24: 22986.18 | BE24: 24231.41 | BF24: 26674.32 | BG24: 25856.04 | BH24: 21428.24 | BI24: 12764.93 | BK24: 12864.69 | BL24: 20613.46 | BM24: 22610.35 | BN24: 21722.88
A25: IBGE:2705804 | B25: AL | C25: Alagoas | D25: OLHO D AGUA DO CASADO | E25: 2705804 | F25: MEDIO | G25: 43559.16 | H25: 42924.76 | I25: 49321.19 | J25: 33835.42 | K25: 46252.14 | L25: 51710.14 | M25: 46018.6 | N25: 49895.49 | O25: 50188.54 | P25: 41267.08 | Q25: 27354.85 | R25: 32650.97 | S25: 31369.49 | T25: 38569.84 | U25: 33683.44 | V25: 38247.58 | W25: 49370.02 | X25: 38551.41 | Y25: 42943.55 | Z25: 46452.31 | AA25: 46933.22 | AB25: 62735.83 | AE25: 48186.95 | AF25: 56984.35 | AG25: 98327.25 | AH25: 55229.76 | AI25: 53193.87 | AJ25: 18163.5 | AK25: 25026.14 | AL25: 26708.76 | AM25: 27399.23 | AN25: 26681.93 | AO25: 25011.79 | AQ25: 27729.36 | AR25: 22792.7 | AS25: 25820.39 | AT25: 23071.42 | AU25: 24821.82 | AV25: 23640.85 | AW25: 26247.19 | AX25: 12727.58 | AY25: 19680.89 | AZ25: 27744.67 | BA25: 25944.4 | BB25: 24065.87 | BC25: 26543.75 | BD25: 21436.33 | BE25: 23574.25 | BF25: 27236.84 | BG25: 26539.37 | BH25: 25885.53 | BI25: 17215.58 | BK25: 24642.85 | BL25: 30891.18 | BM25: 24411.89 | BN25: 22414.38
A26: IBGE:2705705 | B26: AL | C26: Alagoas | D26: OLHO D`AGUA DAS FLORES | E26: 2705705 | F26: MEDIO | G26: 30966.45 | H26: 30116.82 | I26: 30092.57 | J26: 25963.35 | K26: 24252.14 | L26: 27653.88 | M26: 20791 | N26: 27081.69 | O26: 30826.39 | P26: 28102.38 | Q26: 32809.94 | R26: 29635.81 | S26: 28354.33 | T26: 27590.74 | U26: 24833.09 | V26: 29608.27 | W26: 40573.3 | X26: 29754.69 | Y26: 33833.67 | Z26: 37634.39 | AA26: 38321.42 | AB26: 53917.91 | AE26: 55347.03 | AF26: 63363.18 | AG26: 104706.1 | AH26: 58986.37 | AI26: 57680.39 | AJ26: 14532.45 | AK26: 0 | AL26: 18872.24 | AM26: 29290.16 | AN26: 24246.68 | AO26: 23730.31 | AQ26: 25390.48 | AR26: 21382.85 | AS26: 24210.47 | AT26: 21842.89 | AU26: 22453.35 | AV26: 23097.73 | AW26: 26129.65 | AX26: 14357.93 | AY26: 18597.37 | AZ26: 24419.25 | BA26: 24702.76 | BB26: 21167.86 | BC26: 21581.27 | BD26: 19283.91 | BE26: 21137.4 | BF26: 25275.56 | BG26: 22396.46 | BH26: 21972.8 | BI26: 21276.97 | BK26: 22192.96 | BL26: 29364.47 | BM26: 23867.32 | BN26: 23066.07
A27: IBGE:2706000 | B27: AL | C27: Alagoas | D27: OLIVENCA | E27: 2706000 | F27: MEDIO | G27: 75976.09 | H27: 66211.62 | I27: 66211.62 | J27: 62798.38 | K27: 60480.07 | L27: 66501.82 | M27: 65514.07 | N27: 69816.3 | O27: 66189.86 | P27: 64810.05 | Q27: 63966 | R27: 66315.08 | S27: 65033.6 | T27: 56935.1 | U27: 60015.83 | V27: 61555.67 | W27: 73658.87 | X27: 62779.2 | Y27: 66148.64 | Z27: 72297.88 | AA27: 67776.63 | AB27: 87406.75 | AE27: 76150.06 | AF27: 82632.98 | AG27: 127302.91 | AH27: 83729.63 | AI27: 96940.84 | AJ27: 24339.35 | AK27: 0 | AL27: 22353.53 | AM27: 75291.88 | AN27: 70219.71 | AO27: 70247.88 | AQ27: 70990.43 | AR27: 67585.39 | AS27: 71183.38 | AT27: 73054.56 | AU27: 63761.79 | AV27: 67268.43 | AW27: 72734.46 | AX27: 30799.61 | AY27: 63377.32 | AZ27: 69315.38 | BA27: 72552.78 | BB27: 64802.9 | BC27: 69041.95 | BD27: 55051.81 | BE27: 60734.11 | BF27: 69443.97 | BG27: 69778.41 | BH27: 66185.19 | BI27: 70009.66 | BJ27: 42911.35 | BK27: 76887.39 | BL27: 71304.57 | BM27: 61519.88 | BN27: 60528
A28: IBGE:2706109 | B28: AL | C28: Alagoas | D28: OURO BRANCO | E28: 2706109 | F28: MEDIO | G28: 82806.08 | H28: 75582.48 | I28: 72162.47 | J28: 75233.68 | K28: 59585.1 | L28: 83918.99 | M28: 65720.53 | N28: 83466.35 | O28: 84366.7 | P28: 49865.55 | Q28: 51770.87 | R28: 41003 | S28: 51975.45 | T28: 52707.69 | U28: 48296.13 | V28: 52860.27 | W28: 63548.07 | X28: 52729.46 | Y28: 57121.6 | Z28: 63194.77 | AA28: 63881.8 | AB28: 79478.29 | AE28: 62051.47 | AF28: 67017.98 | AG28: 110727.59 | AH28: 67630.09 | AI28: 65155.75 | AJ28: 40440.17 | AK28: 41419.17 | AL28: 41109.45 | AM28: 42376.22 | AN28: 39980.4 | AO28: 34463.9 | AQ28: 39298.69 | AR28: 31663.07 | AS28: 34492.55 | AT28: 82183.33 | AU28: 82148.37 | AV28: 78265.6 | AW28: 84193.56 | AX28: 55317.3 | AY28: 72229.51 | AZ28: 85642.24 | BA28: 84633.23 | BB28: 76887.03 | BC28: 93242.97 | BD28: 73015.47 | BE28: 82031.34 | BF28: 104389.19 | BG28: 95784.57 | BH28: 93397.47 | BI28: 101576.55 | BJ28: 57516.08 | BK28: 92191.98 | BL28: 93885.92 | BM28: 88085.31 | BN28: 95903.63
A29: IBGE:2706406 | B29: AL | C29: Alagoas | D29: PAO DE ACUCAR | E29: 2706406 | F29: MEDIO | G29: 85249.1 | H29: 83584.51 | I29: 54587.23 | J29: 82417.49 | K29: 72699.74 | L29: 84581.39 | M29: 67.97 | N29: 67250.94 | O29: 77776.92 | P29: 73775.33 | Q29: 60499.79 | R29: 79503.89 | S29: 78222.41 | T29: 57931.59 | U29: 70165.06 | V29: 82980.58 | W29: 81565.07 | X29: 71483.81 | Y29: 72133.47 | Z29: 89776.06 | AA29: 83554.1 | AB29: 96303.36 | AE29: 71307.29 | AF29: 75509.27 | AG29: 119950.36 | AH29: 83076.74 | AI29: 71591.97 | AJ29: 20571.63 | AK29: 11544.26 | AL29: 24132.69 | AM29: 38172.19 | AN29: 43458.21 | AO29: 45567.49 | AQ29: 56277.44 | AR29: 42773.17 | AS29: 51909.88 | AT29: 55028.85 | AU29: 56970.14 | AV29: 54473.85 | AW29: 52755.22 | AX29: 21239.81 | AY29: 45532.57 | AZ29: 60980.66 | BA29: 66506.16 | BB29: 56356.79 | BC29: 62321.74 | BD29: 49026.27 | BE29: 47108.09 | BF29: 53745.4 | BG29: 60015.79 | BH29: 57834.92 | BI29: 47856.59 | BJ29: 36782.26 | BK29: 63114.08 | BL29: 67425.68 | BM29: 59315.38 | BN29: 33609.87
A30: IBGE:2706422 | B30: AL | C30: Alagoas | D30: PARICONHA | E30: 2706422 | F30: MEDIO | G30: 41159.82 | H30: 38982.17 | I30: 40584.62 | J30: 36455.43 | K30: 34123.26 | L30: 39315.76 | M30: 38497.9 | N30: 38691.16 | O30: 40018.21 | P30: 37867.1 | Q30: 35828.5 | R30: 37244.82 | S30: 35963.34 | T30: 37281.88 | U30: 32517.68 | V30: 36959.63 | W30: 47186.4 | X30: 36367.79 | Y30: 35747.35 | Z30: 44400.99 | AA30: 42400.45 | AB30: 59903.1 | AE30: 48064.02 | AF30: 54451.41 | AG30: 96720.96 | AH30: 51870.8 | AI30: 61788.37 | AJ30: 35261.65 | AK30: 34208.05 | AL30: 10451.66 | AM30: 18922.92 | AN30: 20353.75 | AO30: 20226.65 | AQ30: 30498.63 | AR30: 26114.18 | AS30: 28825.07 | AT30: 28154.66 | AU30: 27164.34 | AV30: 26810.87 | AW30: 30546.74 | AX30: 15344.22 | AY30: 23049.11 | AZ30: 29046.88 | BA30: 29345.28 | BB30: 24931.94 | BC30: 30455.23 | BD30: 24320.01 | BE30: 26873.86 | BF30: 28183.93 | BG30: 27725.61 | BH30: 23996.98 | BI30: 17397.73 | BJ30: 16467.1 | BK30: 23366.44 | BL30: 30881.21 | BM30: 26400.98 | BN30: 24355.6
A31: IBGE:2707107 | B31: AL | C31: Alagoas | D31: PIRANHAS | E31: 2707107 | F31: MEDIO | G31: 38605.36 | H31: 43912.23 | I31: 42525.92 | J31: 41962.62 | K31: 28804.33 | L31: 48433.37 | M31: 47342.12 | N31: 57130.2 | O31: 46595.15 | P31: 47628.76 | Q31: 38448.58 | R31: 40050.59 | S31: 38769.11 | T31: 51483.87 | U31: 34937.27 | V31: 51161.96 | W31: 61725.81 | X31: 50699.36 | Y31: 55299.33 | Z31: 59563.43 | AA31: 53287.98 | AB31: 69868.91 | AE31: 58394.13 | AF31: 68659.19 | AG31: 110256.2 | AH31: 66618.97 | AI31: 65709.89 | AJ31: 13162.23 | AK31: 41195.23 | AL31: 37253.96 | AM31: 40855.59 | AN31: 38597.6 | AO31: 37800.91 | AQ31: 41468.01 | AR31: 35469.18 | AS31: 39628.06 | AT31: 40480.96 | AU31: 39581.97 | AV31: 41108.62 | AW31: 43320.73 | AX31: 23551.37 | AY31: 34641.99 | AZ31: 39955.79 | BA31: 44626.69 | BB31: 39396.33 | BC31: 42200.65 | BD31: 35449.05 | BE31: 38112.44 | BF31: 39607.31 | BG31: 43152.59 | BH31: 37497.1 | BI31: 43143.86 | BJ31: 24900.81 | BK31: 39138.18 | BL31: 50534.63 | BM31: 43517.36 | BN31: 45095.36
A32: IBGE:2707206 | B32: AL | C32: Alagoas | D32: POCO DAS TRINCHEIRAS | E32: 2707206 | F32: MEDIO | G32: 74013.9 | H32: 60957.72 | I32: 60599.77 | J32: 87640.06 | K32: 56640.08 | L32: 53938.93 | M32: 74570.16 | N32: 53051.13 | O32: 62822.14 | P32: 33572.71 | Q32: 63162.46 | R32: 78732.17 | S32: 78047.57 | T32: 77809.54 | U32: 74089.33 | V32: 75094.8 | W32: 89217.08 | X32: 65033.13 | Y32: 68758.78 | Z32: 88811.25 | AA32: 89495.28 | AB32: 103063.62 | AE32: 113328.37 | AF32: 124367.12 | AG32: 169755.72 | AH32: 124688.36 | AI32: 120226.72 | AJ32: 80308.8 | AK32: 0 | AL32: 13772.37 | AM32: 89398.41 | AN32: 72745.42 | AO32: 108307.36 | AQ32: 113851.83 | AR32: 101371.57 | AS32: 108809.01 | AT32: 114350.74 | AU32: 111089.07 | AV32: 111698.31 | AW32: 115356.52 | AX32: 47983.14 | AY32: 99581.02 | AZ32: 121745.48 | BA32: 127059.78 | BB32: 112850.39 | BC32: 129334.67 | BD32: 115313.6 | BE32: 88744.59 | BF32: 135111.83 | BG32: 144510.13 | BH32: 127375.31 | BI32: 138325.76 | BJ32: 83379.83 | BK32: 142420.09 | BL32: 142389 | BM32: 137684.47 | BN32: 136243.94
A33: IBGE:2707602 | B33: AL | C33: Alagoas | D33: QUEBRANGULO | E33: 2707602 | F33: MEDIO | G33: 24077.66 | H33: 23443.26 | I33: 22974.69 | J33: 19289.82 | K33: 17923.2 | L33: 23661.23 | M33: 22307.57 | N33: 22773.42 | O33: 24532.88 | P33: 21808.37 | Q33: 27917.19 | R33: 29310.34 | S33: 28028.86 | T33: 31782.83 | U33: 27211.35 | V33: 31971.3 | W33: 42470.01 | X33: 30722.77 | Y33: 36043.54 | Z33: 39531.1 | AA33: 36738.52 | AB33: 55814.62 | AE33: 42898.91 | AF33: 49339.6 | AG33: 91725.58 | AH33: 48628.08 | AI33: 45065.62 | AJ33: 13037.68 | AK33: 7115.61 | AL33: 13888.54 | AM33: 17173.38 | AN33: 20805.07 | AO33: 20677.13 | AQ33: 22873.26 | AR33: 16763.14 | AS33: 19733.04 | AT33: 18280.89 | AU33: 16091.31 | AY33: 16088.85 | AZ33: 37328.96 | BA33: 32494.53 | BB33: 32254.98 | BC33: 41052.32 | BD33: 33682.03 | BE33: 35264.9 | BF33: 45152.6 | BG33: 43497.6 | BH33: 42854.09 | BI33: 44649.29 | BJ33: 27376.93 | BK33: 40748.87 | BL33: 45337.14 | BM33: 41452.54 | BN33: 40743.54
A34: IBGE:2708006 | B34: AL | C34: Alagoas | D34: SANTANA DO IPANEMA | E34: 2708006 | F34: MEDIO | G34: 51750.8 | H34: 50628.53 | I34: 52033.08 | J34: 51287.89 | K34: 38328.18 | L34: 55218.68 | M34: 50213.12 | N34: 54482.92 | O34: 55790.07 | P34: 42392.96 | Q34: 51385.6 | R34: 53227.41 | S34: 64202.27 | T34: 64031.87 | U34: 59018.83 | V34: 64179.54 | W34: 70344.43 | X34: 63193.76 | Y34: 64167.27 | Z34: 70927.18 | AA34: 68764.62 | AB34: 81187.08 | AE34: 75056.7 | AF34: 78282.75 | AG34: 123668.81 | AH34: 80571.31 | AI34: 83522.79 | AJ34: 40619.9 | AK34: 23118.15 | AL34: 16709.13 | AM34: 49167.92 | AN34: 56048.41 | AO34: 60581.06 | AQ34: 65355.09 | AR34: 55609.76 | AS34: 60767.09 | AT34: 62149.69 | AU34: 60444.54 | AV34: 58473.59 | AW34: 62003.09 | AX34: 27487.83 | AY34: 51264.94 | AZ34: 72023.72 | BA34: 70305.18 | BB34: 65220.23 | BC34: 72575.77 | BD34: 55771.97 | BE34: 63728.22 | BF34: 80106.2 | BG34: 76285.91 | BH34: 65822.9 | BI34: 58387.65 | BJ34: 54419.06 | BK34: 84240.38 | BL34: 83845.05 | BM34: 75948.78 | BN34: 78425.65
A35: IBGE:2708204 | B35: AL | C35: Alagoas | D35: SAO BRAS | E35: 2708204 | F35: MEDIO | G35: 17587.43 | H35: 16953.03 | I35: 16953.03 | J35: 12799.59 | K35: 11478.25 | L35: 17206.25 | M35: 12852.59 | N35: 15685.95 | O35: 18077.9 | P35: 15690.38 | Q35: 20397.94 | R35: 22239.75 | S35: 20958.27 | T35: 24216.48 | U35: 19940.13 | V35: 24504.27 | W35: 34712.2 | X35: 23474.64 | Y35: 27866.78 | Z35: 30516.44 | AA35: 32041.37 | AB35: 48056.81 | AE35: 36641.04 | AF35: 39794.23 | AG35: 83018.14 | AH35: 39920.64 | AI35: 37233.62 | AJ35: 7359.93 | AK35: 0 | AL35: 8028.42
A36: IBGE:2708402 | B36: AL | C36: Alagoas | D36: SAO JOSE DA TAPERA | E36: 2708402 | F36: MEDIO | G36: 90028.3 | H36: 70543.38 | I36: 16928.78 | J36: 85786.63 | K36: 73263 | L36: 89833.72 | M36: 88130.32 | N36: 93114.57 | O36: 81894.97 | P36: 66892.18 | Q36: 81725.55 | R36: 55449.19 | S36: 67786.33 | T36: 83431.58 | U36: 82870.64 | V36: 84837.71 | W36: 88165.88 | X36: 71721.83 | Y36: 75860.69 | Z36: 93189.68 | AA36: 85581.57 | AB36: 98596.07 | AE36: 97409 | AF36: 102024.02 | AG36: 146703.14 | AH36: 101703.64 | AI36: 128640.24 | AJ36: 103473.81 | AK36: 43775.69 | AL36: 31556.35 | AM36: 88660.44 | AN36: 96448.76 | AO36: 93460.89 | AQ36: 105656.91 | AR36: 88727.93 | AS36: 94410.05 | AT36: 98303.83 | AU36: 99586.59 | AV36: 90493.22 | AW36: 102312.46 | AX36: 44359.19 | AY36: 88298.81 | AZ36: 99196.43 | BA36: 96896.84 | BB36: 92765.11 | BC36: 98824.98 | BD36: 84428.43 | BE36: 90996.53 | BF36: 105567.63 | BG36: 104945.02 | BH36: 85707.06 | BI36: 103078.93 | BJ36: 67420.85 | BK36: 109517.44 | BL36: 103742.35 | BM36: 93996.63 | BN36: 95258.04
A37: IBGE:2708956 | B37: AL | C37: Alagoas | D37: SENADOR RUI PALMEIRA | E37: 2708956 | F37: MEDIO | G37: 195241.41 | H37: 203261.98 | I37: 196553.86 | J37: 200248.29 | K37: 57573.53 | L37: 191462.75 | M37: 191290.44 | N37: 180702.92 | O37: 195467.47 | P37: 188658.25 | Q37: 104939.75 | R37: 110219.5 | S37: 123202.52 | T37: 118058.39 | U37: 113990.19 | V37: 118846.26 | W37: 131207.5 | X37: 120786.95 | Y37: 122467.77 | Z37: 131494.72 | AA37: 131721.61 | AB37: 144981.33 | AE37: 128629.17 | AF37: 128498.92 | AG37: 176624.01 | AH37: 132645.65 | AI37: 130340.18 | AJ37: 87967.99 | AK37: 109064.24 | AL37: 106431.65 | AM37: 118174.17 | AN37: 113105.09 | AO37: 99771.97 | AQ37: 104908.79 | AR37: 92158.19 | AS37: 123307.76 | AT37: 160385.71 | AU37: 169025.93 | AV37: 155835.97 | AW37: 170968.19 | AX37: 68733.18 | AY37: 140812.86 | AZ37: 156607.73 | BA37: 150172.33 | BB37: 143528.06 | BC37: 150709.32 | BD37: 127046.88 | BE37: 141190.29 | BF37: 157683.57 | BG37: 166276.02 | BH37: 143161.81 | BI37: 198797.77 | BJ37: 123259.38 | BK37: 206657.74 | BL37: 195092.01 | BM37: 186408.13 | BN37: 191108.9
A38: IBGE:2709202 | B38: AL | C38: Alagoas | D38: TRAIPU | E38: 2709202 | F38: MEDIO | G38: 0 | H38: 0 | I38: 0 | J38: 0 | K38: 0 | L38: 0 | M38: 0 | N38: 0 | O38: 0 | P38: 0 | Q38: 102433.19 | R38: 82538.96 | S38: 102287.92 | T38: 97748.19 | U38: 100188.92 | V38: 97510.21 | W38: 118511.81 | X38: 94516.8 | Y38: 105799.26 | Z38: 113926.21 | AA38: 106036.64 | AB38: 110328.3 | AE38: 79093.51 | AF38: 70202.04 | AG38: 122530.78 | AH38: 67407.63 | AI38: 71492.53 | AJ38: 7342.07 | AK38: 0 | AL38: 22508.37 | AM38: 30505.65 | AN38: 46148.94 | AO38: 54963.12 | AQ38: 71781.53 | AR38: 56894.83 | AS38: 67518.04 | AT38: 64232.77 | AU38: 56556.73 | AY38: 33844.99 | AZ38: 52463.98 | BA38: 54794.6 | BB38: 53377.65 | BC38: 84655.87 | BD38: 77353.03 | BE38: 46279.59 | BF38: 50480.89 | BG38: 77799.62 | BH38: 67659.19 | BI38: 67180.32 | BJ38: 46504.52 | BK38: 75340.53 | BL38: 77992.68 | BM38: 71658.21 | BN38: 64327.61
A39: IBGE:2900207 | B39: BA | C39: Bahia | D39: ABARE | E39: 2900207 | F39: MEDIO | G39: 72607.22 | H39: 66017.59 | I39: 69293.45 | J39: 79427.98 | K39: 77104.14 | L39: 68004.6 | M39: 59258.97 | N39: 55766.69 | O39: 51959.38 | P39: 54856.69 | Q39: 55903.08 | R39: 53886.42 | S39: 54236.42 | T39: 57991.3 | U39: 57991.3 | V39: 55508.34 | W39: 57295.52 | X39: 60558.37 | Y39: 59844.08 | Z39: 55261.62 | AA39: 50717.58 | AB39: 49980.66 | AE39: 41252.56 | AF39: 48506.57 | AG39: 49160.28 | AH39: 56203.81 | AI39: 53987.9 | AJ39: 61974.27 | AK39: 37217.29 | AL39: 53024.34 | AM39: 44369.67 | AN39: 44973.65 | AO39: 48297.33 | AQ39: 44396.31 | AR39: 22634.38 | AS39: 19215.46 | AT39: 38412.32 | AU39: 44183.39 | AV39: 39124.6 | AW39: 34347.85 | AX39: 39584.39 | AY39: 40422.68 | AZ39: 37102.9 | BA39: 37400.52 | BB39: 21461.94 | BC39: 44872.38 | BD39: 29860.88 | BE39: 37517.11 | BF39: 44890.94 | BG39: 30877.14 | BH39: 26364.32 | BI39: 38447.72 | BJ39: 41158.61 | BK39: 34526.15 | BL39: 32607.93 | BM39: 33583.21 | BN39: 36095.71
A40: IBGE:2901155 | B40: BA | C40: Bahia | D40: AMERICA DOURADA | E40: 2901155 | F40: MEDIO | G40: 35813.6 | H40: 16188.16 | I40: 0 | J40: 29721.9 | K40: 21104.98 | L40: 25647.67 | M40: 24650.55 | N40: 17935.05 | O40: 15938.7 | P40: 18449.37 | Q40: 13688.26 | R40: 14762.56 | S40: 11457.78 | T40: 0 | U40: 0 | V40: 24814.13 | W40: 22039.43 | X40: 18000.86 | Y40: 18000.86 | Z40: 13294.97 | AA40: 15319.01 | AB40: 11720.93 | AE40: 0 | AF40: 14292.19 | AG40: 14774.11 | AH40: 27017.74 | AI40: 24762.55 | AJ40: 28606.12 | AK40: 23708 | AL40: 27313.86 | AM40: 13983.65 | AN40: 11381.47 | AO40: 6838.32 | AQ40: 11197.46 | AR40: 18916.04 | AS40: 21363.52 | AT40: 11785.96 | AU40: 0 | AV40: 18197.26 | AW40: 27141.79 | AX40: 20007.13 | AY40: 17494.91 | AZ40: 19427.29 | BA40: 25997.06 | BB40: 6587.45 | BC40: 0 | BD40: 18905.87 | BE40: 17217.74 | BG40: 0 | BH40: 17063.82 | BI40: 20984.9 | BJ40: 19286.84 | BK40: 18004.47 | BL40: 17497.51 | BM40: 19548.86
...

Sheet deflatores_ipca
A1: data | B1: ano e mês | C1: ipca_var_pct | D1: It (base dez/2019 = 1) | E1: Dt = 1/It
A2: 42005 | B2: 2015-01 | C2: 1.24 | D2: =D3/(1+C3/100) -> 0.77255644 | E2: =1/D2 -> 1.2944038
A3: 42036 | B3: 2015-02 | C3: 1.22 | D3: =D4/(1+C4/100) -> 0.78198163 | E3: =1/D3 -> 1.2788024
A4: 42064 | B4: 2015-03 | C4: 1.32 | D4: =D5/(1+C5/100) -> 0.79230379 | E4: =1/D4 -> 1.2621421
A5: 42095 | B5: 2015-04 | C5: 0.71 | D5: =D6/(1+C6/100) -> 0.79792914 | E5: =1/D5 -> 1.2532441
A6: 42125 | B6: 2015-05 | C6: 0.74 | D6: =D7/(1+C7/100) -> 0.80383382 | E6: =1/D6 -> 1.2440382
A7: 42156 | B7: 2015-06 | C7: 0.79 | D7: =D8/(1+C8/100) -> 0.81018411 | E7: =1/D7 -> 1.2342874
A8: 42186 | B8: 2015-07 | C8: 0.62 | D8: =D9/(1+C9/100) -> 0.81520725 | E8: =1/D8 -> 1.2266819
A9: 42217 | B9: 2015-08 | C9: 0.22 | D9: =D10/(1+C10/100) -> 0.8170007 | E9: =1/D9 -> 1.2239892
A10: 42248 | B10: 2015-09 | C10: 0.54 | D10: =D11/(1+C11/100) -> 0.82141251 | E10: =1/D10 -> 1.2174151
A11: 42278 | B11: 2015-10 | C11: 0.82 | D11: =D12/(1+C12/100) -> 0.82814809 | E11: =1/D11 -> 1.2075135
A12: 42309 | B12: 2015-11 | C12: 1.01 | D12: =D13/(1+C13/100) -> 0.83651239 | E12: =1/D12 -> 1.1954396
A13: 42339 | B13: 2015-12 | C13: 0.96 | D13: =D14/(1+C14/100) -> 0.8445429 | E13: =1/D13 -> 1.1840725
... A60: 43770 | B60: 2019-11 | C60: 0.51 | D60: =D61/(1+C61/100) -> 0.98863075 | E60: =1/D60 -> 1.0115
A61: 43800 | B61: 2019-12 | C61: 1.15 | D61: =1 -> 1 | E61: =1/D61 -> 1

Sheet CUSTOS REAL_dez2019
A1: key | B1: UF | C1: Estado | D1: Municipio | E1: IBGE | F1: tipo_coluna | G1: 2015-01 | H1: 2015-02 | I1: 2015-03 | J1: 2015-04 | K1: 2015-05 | L1: 2015-06 | M1: 2015-07 | N1: 2015-08 | O1: 2015-09 | P1: 2015-10 | Q1: 2015-11 | R1: 2015-12 | S1: 2016-01 | T1: 2016-02 | U1: 2016-03 | V1: 2016-04 | W1: 2016-05 | X1: 2016-06 | Y1: 2016-07 | Z1: 2016-08 | AA1: 2016-09 | AB1: 2016-10 | AC1: 2016-11 | AD1: 2016-12 | AE1: 2017-01 | AF1: 2017-02 | AG1: 2017-03 | AH1: 2017-04 | AI1: 2017-05 | AJ1: 2017-06 | AK1: 2017-07 | AL1: 2017-08 | AM1: 2017-09 | AN1: 2017-10 | AO1: 2017-11 | AP1: 2017-12 | AQ1: 2018-01 | AR1: 2018-02 | AS1: 2018-03 | AT1: 2018-04 | AU1: 2018-05 | AV1: 2018-06 | AW1: 2018-07 | AX1: 2018-08 | AY1: 2018-09 | AZ1: 2018-10 | BA1: 2018-11 | BB1: 2018-12 | BC1: 2019-01 | BD1: 2019-02 | BE1: 2019-03 | BF1: 2019-04 | BG1: 2019-05 | BH1: 2019-06 | BI1: 2019-07 | BJ1: 2019-08 | BK1: 2019-09 | BL1: 2019-10 | BM1: 2019-11 | BN1: 2019-12
A2: IBGE:2700102 | B2: AL | C2: Alagoas | D2: AGUA BRANCA | E2: 2700102 | F2: MEDIO | G2: =CUSTOS_nominal!G2*VLOOKUP(G$1,deflatores_ipca!$B$2:$E$61,4,FALSE) -> 104432.31 | H2: =CUSTOS_nominal!H2*VLOOKUP(H$1,deflatores_ipca!$B$2:$E$61,4,FALSE) -> 100013.96 | I2: =CUSTOS_nominal!I2*VLOOKUP(I$1,deflatores_ipca!$B$2:$E$61,4,FALSE) -> 98536.51 | J2: =CUSTOS_nominal!J2*VLOOKUP(J$1,deflatores_ipca!$B$2:$E$61,4,FALSE) -> 69231.135 | K2: =CUSTOS_nominal!K2*VLOOKUP(K$1,deflatores_ipca!$B$2:$E$61,4,FALSE) -> 83025.606 | L2: =CUSTOS_nominal!L2*VLOOKUP(L$1,deflatores_ipca!$B$2:$E$61,4,FALSE) -> 91455.003 | M2: =CUSTOS_nominal!M2*VLOOKUP(M$1,deflatores_ipca!$B$2:$E$61,4,FALSE) -> 87449.615 | N2: =CUSTOS_nominal!N2*VLOOKUP(N$1,deflatores_ipca!$B$2:$E$61,4,FALSE) -> 90491.134 | ... AB2: =CUSTOS_nominal!AB2*VLOOKUP(AB$1,deflatores_ipca!$B$2:$E$61,4,FALSE) -> 80483.174 | AE2: =CUSTOS_nominal!AE2*VLOOKUP(AE$1,deflatores_ipca!$B$2:$E$61,4,FALSE) -> 76124.602 | AF2: =CUSTOS_nominal!AF2*VLOOKUP(AF$1,deflatores_ipca!$B$2:$E$61,4,FALSE) -> 71523.003 | AG2: =CUSTOS_nominal!AG2*VLOOKUP(AG$1,deflatores_ipca!$B$2:$E$61,4,FALSE) -> 124568.55 | AH2: =CUSTOS_nominal!AH2*VLOOKUP(AH$1,deflatores_ipca!$B$2:$E$61,4,FALSE) -> 72018.301 | AI2: =CUSTOS_nominal!AI2*VLOOKUP(AI$1,deflatores_ipca!$B$2:$E$61,4,FALSE) -> 77837.782 | AJ2: =CUSTOS_nominal!AJ2*VLOOKUP(AJ$1,deflatores_ipca!$B$2:$E$61,4,FALSE) -> 35415.197 | AK2: =CUSTOS_nominal!AK2*VLOOKUP(AK$1,deflatores_ipca!$B$2:$E$61,4,FALSE) -> 0 | AL2: =CUSTOS_nominal!AL2*VLOOKUP(AL$1,deflatores_ipca!$B$2:$E$61,4,FALSE) -> 9127.7703 | ... AO2: =CUSTOS_nominal!AO2*VLOOKUP(AO$1,deflatores_ipca!$B$2:$E$61,4,FALSE) -> 45080.771 | AQ2: =CUSTOS_nominal!AQ2*VLOOKUP(AQ$1,deflatores_ipca!$B$2:$E$61,4,FALSE) -> 69539.011 | AR2: =CUSTOS_nominal!AR2*VLOOKUP(AR$1,deflatores_ipca!$B$2:$E$61,4,FALSE) -> 57693.381 | AS2: =CUSTOS_nominal!AS2*VLOOKUP(AS$1,deflatores_ipca!$B$2:$E$61,4,FALSE) -> 65028.332 | AT2: =CUSTOS_nominal!AT2*VLOOKUP(AT$1,deflatores_ipca!$B$2:$E$61,4,FALSE) -> 69528.763 | AU2: =CUSTOS_nominal!AU2*VLOOKUP(AU$1,deflatores_ipca!$B$2:$E$61,4,FALSE) -> 67511.836 | AV2: =CUSTOS_nominal!AV2*VLOOKUP(AV$1,deflatores_ipca!$B$2:$E$61,4,FALSE) -> 68169.763 | AW2: =CUSTOS_nominal!AW2*VLOOKUP(AW$1,deflatores_ipca!$B$2:$E$61,4,FALSE) -> 71181.876 | AX2: =CUSTOS_nominal!AX2*VLOOKUP(AX$1,deflatores_ipca!$B$2:$E$61,4,FALSE) -> 23292.851 | ... BN2: =CUSTOS_nominal!BN2*VLOOKUP(BN$1,deflatores_ipca!$B$2:$E$61,4,FALSE) -> 60434.82
A3: IBGE:2700706 | B3: AL | C3: Alagoas | D3: BATALHA | E3: 2700706 | F3: MEDIO | G3: =CUSTOS_nominal!G3*VLOOKUP(G$1,deflatores_ipca!$B$2:$E$61,4,FALSE) -> 79942.871 | H3: =CUSTOS_nominal!H3*VLOOKUP(H$1,deflatores_ipca!$B$2:$E$61,4,FALSE) -> 77948.072 | I3: =CUSTOS_nominal!I3*VLOOKUP(I$1,deflatores_ipca!$B$2:$E$61,4,FALSE) -> 76901.955 | J3: =CUSTOS_nominal!J3*VLOOKUP(J$1,deflatores_ipca!$B$2:$E$61,4,FALSE) -> 53962.962 | K3: =CUSTOS_nominal!K3*VLOOKUP(K$1,deflatores_ipca!$B$2:$E$61,4,FALSE) -> 64359.347 | L3: =CUSTOS_nominal!L3*VLOOKUP(L$1,deflatores_ipca!$B$2:$E$61,4,FALSE) -> 46462.02 | M3: =CUSTOS_nominal!M3*VLOOKUP(M$1,deflatores_ipca!$B$2:$E$61,4,FALSE) -> 54744.778 | N3: =CUSTOS_nominal!N3*VLOOKUP(N$1,deflatores_ipca!$B$2:$E$61,4,FALSE) -> 72902.863 | ... AB3: =CUSTOS_nominal!AB3*VLOOKUP(AB$1,deflatores_ipca!$B$2:$E$61,4,FALSE) -> 97664.826 | AE3: =CUSTOS_nominal!AE3*VLOOKUP(AE$1,deflatores_ipca!$B$2:$E$61,4,FALSE) -> 76630.607 | AF3: =CUSTOS_nominal!AF3*VLOOKUP(AF$1,deflatores_ipca!$B$2:$E$61,4,FALSE) -> 89178.79 | AG3: =CUSTOS_nominal!AG3*VLOOKUP(AG$1,deflatores_ipca!$B$2:$E$61,4,FALSE) -> 137474.61 | AH3: =CUSTOS_nominal!AH3*VLOOKUP(AH$1,deflatores_ipca!$B$2:$E$61,4,FALSE) -> 90591.231 | AI3: =CUSTOS_nominal!AI3*VLOOKUP(AI$1,deflatores_ipca!$B$2:$E$61,4,FALSE) -> 78224.359 | AJ3: =CUSTOS_nominal!AJ3*VLOOKUP(AJ$1,deflatores_ipca!$B$2:$E$61,4,FALSE) -> 48826.869 | AK3: =CUSTOS_nominal!AK3*VLOOKUP(AK$1,deflatores_ipca!$B$2:$E$61,4,FALSE) -> 43578.752 | AL3: =CUSTOS_nominal!AL3*VLOOKUP(AL$1,deflatores_ipca!$B$2:$E$61,4,FALSE) -> 47306.616 | ... AO3: =CUSTOS_nominal!AO3*VLOOKUP(AO$1,deflatores_ipca!$B$2:$E$61,4,FALSE) -> 49748.743 | AQ3: =CUSTOS_nominal!AQ3*VLOOKUP(AQ$1,deflatores_ipca!$B$2:$E$61,4,FALSE) -> 53294.757 | AR3: =CUSTOS_nominal!AR3*VLOOKUP(AR$1,deflatores_ipca!$B$2:$E$61,4,FALSE) -> 44971.454 | AS3: =CUSTOS_nominal!AS3*VLOOKUP(AS$1,deflatores_ipca!$B$2:$E$61,4,FALSE) -> 48153.422 | AT3: =CUSTOS_nominal!AT3*VLOOKUP(AT$1,deflatores_ipca!$B$2:$E$61,4,FALSE) -> 49388.563 | AU3: =CUSTOS_nominal!AU3*VLOOKUP(AU$1,deflatores_ipca!$B$2:$E$61,4,FALSE) -> 47689.775 | AV3: =CUSTOS_nominal!AV3*VLOOKUP(AV$1,deflatores_ipca!$B$2:$E$61,4,FALSE) -> 46234.948 | AW3: =CUSTOS_nominal!AW3*VLOOKUP(AW$1,deflatores_ipca!$B$2:$E$61,4,FALSE) -> 68086.393 | AX3: =CUSTOS_nominal!AX3*VLOOKUP(AX$1,deflatores_ipca!$B$2:$E$61,4,FALSE) -> 27502.854 | ... BN3: =CUSTOS_nominal!BN3*VLOOKUP(BN$1,deflatores_ipca!$B$2:$E$61,4,FALSE) -> 46841.43
A4: IBGE:2501906 | B4: AL | C4: Alagoas | D4: BELEM | E4: 2501906 | F4: MEDIO | G4: =CUSTOS_nominal!G4*VLOOKUP(G$1,deflatores_ipca!$B$2:$E$61,4,FALSE) -> 41512.462 | H4: =CUSTOS_nominal!H4*VLOOKUP(H$1,deflatores_ipca!$B$2:$E$61,4,FALSE) -> 39127.684 | I4: =CUSTOS_nominal!I4*VLOOKUP(I$1,deflatores_ipca!$B$2:$E$61,4,FALSE) -> 38587.32 | J4: =CUSTOS_nominal!J4*VLOOKUP(J$1,deflatores_ipca!$B$2:$E$61,4,FALSE) -> 33140.399 | K4: =CUSTOS_nominal!K4*VLOOKUP(K$1,deflatores_ipca!$B$2:$E$61,4,FALSE) -> 20041.58 | L4: =CUSTOS_nominal!L4*VLOOKUP(L$1,deflatores_ipca!$B$2:$E$61,4,FALSE) -> 38026.098 | M4: =CUSTOS_nominal!M4*VLOOKUP(M$1,deflatores_ipca!$B$2:$E$61,4,FALSE) -> 36131.278 | N4: =CUSTOS_nominal!N4*VLOOKUP(N$1,deflatores_ipca!$B$2:$E$61,4,FALSE) -> 37181.547 | ... AB4: =CUSTOS_nominal!AB4*VLOOKUP(AB$1,deflatores_ipca!$B$2:$E$61,4,FALSE) -> 62454.177 | AE4: =CUSTOS_nominal!AE4*VLOOKUP(AE$1,deflatores_ipca!$B$2:$E$61,4,FALSE) -> 28449.171 | AF4: =CUSTOS_nominal!AF4*VLOOKUP(AF$1,deflatores_ipca!$B$2:$E$61,4,FALSE) -> 32429.017 | AG4: =CUSTOS_nominal!AG4*VLOOKUP(AG$1,deflatores_ipca!$B$2:$E$61,4,FALSE) -> 55526.35 | AH4: =CUSTOS_nominal!AH4*VLOOKUP(AH$1,deflatores_ipca!$B$2:$E$61,4,FALSE) -> 32409.533 | AI4: =CUSTOS_nominal!AI4*VLOOKUP(AI$1,deflatores_ipca!$B$2:$E$61,4,FALSE) -> 31143.871 | AJ4: =CUSTOS_nominal!AJ4*VLOOKUP(AJ$1,deflatores_ipca!$B$2:$E$61,4,FALSE) -> 10914.004 | AK4: =CUSTOS_nominal!AK4*VLOOKUP(AK$1,deflatores_ipca!$B$2:$E$61,4,FALSE) -> 10527.341 | AL4: =CUSTOS_nominal!AL4*VLOOKUP(AL$1,deflatores_ipca!$B$2:$E$61,4,FALSE) -> 14916.322 | ... AO4: =CUSTOS_nominal!AO4*VLOOKUP(AO$1,deflatores_ipca!$B$2:$E$61,4,FALSE) -> 0 | AQ4: =CUSTOS_nominal!AQ4*VLOOKUP(AQ$1,deflatores_ipca!$B$2:$E$61,4,FALSE) -> 0 | AR4: =CUSTOS_nominal!AR4*VLOOKUP(AR$1,deflatores_ipca!$B$2:$E$61,4,FALSE) -> 0 | AS4: =CUSTOS_nominal!AS4*VLOOKUP(AS$1,deflatores_ipca!$B$2:$E$61,4,FALSE) -> 0 | AT4: =CUSTOS_nominal!AT4*VLOOKUP(AT$1,deflatores_ipca!$B$2:$E$61,4,FALSE) -> 0 | AU4: =CUSTOS_nominal!AU4*VLOOKUP(AU$1,deflatores_ipca!$B$2:$E$61,4,FALSE) -> 0 | AV4: =CUSTOS_nominal!AV4*VLOOKUP(AV$1,deflatores_ipca!$B$2:$E$61,4,FALSE) -> 0 | AW4: =CUSTOS_nominal!AW4*VLOOKUP(AW$1,deflatores_ipca!$B$2:$E$61,4,FALSE) -> 0 | AX4: =CUSTOS_nominal!AX4*VLOOKUP(AX$1,deflatores_ipca!$B$2:$E$61,4,FALSE) -> 0 | ... BN4: =CUSTOS_nominal!BN4*VLOOKUP(BN$1,deflatores_ipca!$B$2:$E$61,4,FALSE) -> 0
A5: IBGE:2700904 | B5: AL | C5: Alagoas | D5: BELO MONTE | E5: 2700904 | F5: MEDIO | G5: =CUSTOS_nominal!G5*VLOOKUP(G$1,deflatores_ipca!$B$2:$E$61,4,FALSE) -> 46637.667 | H5: =CUSTOS_nominal!H5*VLOOKUP(H$1,deflatores_ipca!$B$2:$E$61,4,FALSE) -> 45703.03 | I5: =CUSTOS_nominal!I5*VLOOKUP(I$1,deflatores_ipca!$B$2:$E$61,4,FALSE) -> 50125.571 | J5: =CUSTOS_nominal!J5*VLOOKUP(J$1,deflatores_ipca!$B$2:$E$61,4,FALSE) -> 39583.314 | K5: =CUSTOS_nominal!K5*VLOOKUP(K$1,deflatores_ipca!$B$2:$E$61,4,FALSE) -> 39292.549 | L5: =CUSTOS_nominal!L5*VLOOKUP(L$1,deflatores_ipca!$B$2:$E$61,4,FALSE) -> 22203.348 | M5: =CUSTOS_nominal!M5*VLOOKUP(M$1,deflatores_ipca!$B$2:$E$61,4,FALSE) -> 36122.52 | N5: =CUSTOS_nominal!N5*VLOOKUP(N$1,deflatores_ipca!$B$2:$E$61,4,FALSE) -> 43946.229 | ... AB5: =CUSTOS_nominal!AB5*VLOOKUP(AB$1,deflatores_ipca!$B$2:$E$61,4,FALSE) -> 102402.74 | AE5: =CUSTOS_nominal!AE5*VLOOKUP(AE$1,deflatores_ipca!$B$2:$E$61,4,FALSE) -> 87211.919 | AF5: =CUSTOS_nominal!AF5*VLOOKUP(AF$1,deflatores_ipca!$B$2:$E$61,4,FALSE) -> 89302.746 | AG5: =CUSTOS_nominal!AG5*VLOOKUP(AG$1,deflatores_ipca!$B$2:$E$61,4,FALSE) -> 138732.28 | AH5: =CUSTOS_nominal!AH5*VLOOKUP(AH$1,deflatores_ipca!$B$2:$E$61,4,FALSE) -> 90807.569 | AI5: =CUSTOS_nominal!AI5*VLOOKUP(AI$1,deflatores_ipca!$B$2:$E$61,4,FALSE) -> 57403.348 | AJ5: =CUSTOS_nominal!AJ5*VLOOKUP(AJ$1,deflatores_ipca!$B$2:$E$61,4,FALSE) -> 30870.812 | AK5: =CUSTOS_nominal!AK5*VLOOKUP(AK$1,deflatores_ipca!$B$2:$E$61,4,FALSE) -> 16538.916 | AL5: =CUSTOS_nominal!AL5*VLOOKUP(AL$1,deflatores_ipca!$B$2:$E$61,4,FALSE) -> 10942.61 | ... AO5: =CUSTOS_nominal!AO5*VLOOKUP(AO$1,deflatores_ipca!$B$2:$E$61,4,FALSE) -> 39752.295 | AQ5: =CUSTOS_nominal!AQ5*VLOOKUP(AQ$1,deflatores_ipca!$B$2:$E$61,4,FALSE) -> 41893.019 | AR5: =CUSTOS_nominal!AR5*VLOOKUP(AR$1,deflatores_ipca!$B$2:$E$61,4,FALSE) -> 36157.489 | AS5: =CUSTOS_nominal!AS5*VLOOKUP(AS$1,deflatores_ipca!$B$2:$E$61,4,FALSE) -> 39437.261 | AT5: =CUSTOS_nominal!AT5*VLOOKUP(AT$1,deflatores_ipca!$B$2:$E$61,4,FALSE) -> 38200.475 | AU5: =CUSTOS_nominal!AU5*VLOOKUP(AU$1,deflatores_ipca!$B$2:$E$61,4,FALSE) -> 39117.789 | AV5: =CUSTOS_nominal!AV5*VLOOKUP(AV$1,deflatores_ipca!$B$2:$E$61,4,FALSE) -> 37135.516 | AW5: =CUSTOS_nominal!AW5*VLOOKUP(AW$1,deflatores_ipca!$B$2:$E$61,4,FALSE) -> 67507.749 | AX5: =CUSTOS_nominal!AX5*VLOOKUP(AX$1,deflatores_ipca!$B$2:$E$61,4,FALSE) -> 34964.617 | ... BN5: =CUSTOS_nominal!BN5*VLOOKUP(BN$1,deflatores_ipca!$B$2:$E$61,4,FALSE) -> 67917.2
A6: IBGE:2701209 | B6: AL | C6: Alagoas | D6: CACIMBINHAS | E6: 2701209 | F6: MEDIO | G6: =CUSTOS_nominal!G6*VLOOKUP(G$1,deflatores_ipca!$B$2:$E$61,4,FALSE) -> 0 | H6: =CUSTOS_nominal!H6*VLOOKUP(H$1,deflatores_ipca!$B$2:$E$61,4,FALSE) -> 0 | I6: =CUSTOS_nominal!I6*VLOOKUP(I$1,deflatores_ipca!$B$2:$E$61,4,FALSE) -> 0 | J6: =CUSTOS_nominal!J6*VLOOKUP(J$1,deflatores_ipca!$B$2:$E$61,4,FALSE) -> 0 | K6: =CUSTOS_nominal!K6*VLOOKUP(K$1,deflatores_ipca!$B$2:$E$61,4,FALSE) -> 0 | L6: =CUSTOS_nominal!L6*VLOOKUP(L$1,deflatores_ipca!$B$2:$E$61,4,FALSE) -> 0 | M6: =CUSTOS_nominal!M6*VLOOKUP(M$1,deflatores_ipca!$B$2:$E$61,4,FALSE) -> 0 | N6: =CUSTOS_nominal!N6*VLOOKUP(N$1,deflatores_ipca!$B$2:$E$61,4,FALSE) -> 0 | ... AB6: =CUSTOS_nominal!AB6*VLOOKUP(AB$1,deflatores_ipca!$B$2:$E$61,4,FALSE) -> 180248.84 | AE6: =CUSTOS_nominal!AE6*VLOOKUP(AE$1,deflatores_ipca!$B$2:$E$61,4,FALSE) -> 165559.94 | AF6: =CUSTOS_nominal!AF6*VLOOKUP(AF$1,deflatores_ipca!$B$2:$E$61,4,FALSE) -> 169924.32 | AG6: =CUSTOS_nominal!AG6*VLOOKUP(AG$1,deflatores_ipca!$B$2:$E$61,4,FALSE) -> 218145.3 | AH6: =CUSTOS_nominal!AH6*VLOOKUP(AH$1,deflatores_ipca!$B$2:$E$61,4,FALSE) -> 171145.29 | AI6: =CUSTOS_nominal!AI6*VLOOKUP(AI$1,deflatores_ipca!$B$2:$E$61,4,FALSE) -> 181931.82 | AJ6: =CUSTOS_nominal!AJ6*VLOOKUP(AJ$1,deflatores_ipca!$B$2:$E$61,4,FALSE) -> 27850.129 | AK6: =CUSTOS_nominal!AK6*VLOOKUP(AK$1,deflatores_ipca!$B$2:$E$61,4,FALSE) -> 8527.7995 | AL6: =CUSTOS_nominal!AL6*VLOOKUP(AL$1,deflatores_ipca!$B$2:$E$61,4,FALSE) -> 83318.449 | ... AO6: =CUSTOS_nominal!AO6*VLOOKUP(AO$1,deflatores_ipca!$B$2:$E$61,4,FALSE) -> 141301.82 | AQ6: =CUSTOS_nominal!AQ6*VLOOKUP(AQ$1,deflatores_ipca!$B$2:$E$61,4,FALSE) -> 157412.42 | AR6: =CUSTOS_nominal!AR6*VLOOKUP(AR$1,deflatores_ipca!$B$2:$E$61,4,FALSE) -> 136495.07 | AS6: =CUSTOS_nominal!AS6*VLOOKUP(AS$1,deflatores_ipca!$B$2:$E$61,4,FALSE) -> 150653.33 | AT6: =CUSTOS_nominal!AT6*VLOOKUP(AT$1,deflatores_ipca!$B$2:$E$61,4,FALSE) -> 144308.24 | AU6: =CUSTOS_nominal!AU6*VLOOKUP(AU$1,deflatores_ipca!$B$2:$E$61,4,FALSE) -> 137762.14 | AV6: =CUSTOS_nominal!AV6*VLOOKUP(AV$1,deflatores_ipca!$B$2:$E$61,4,FALSE) -> 142905.53 | AW6: =CUSTOS_nominal!AW6*VLOOKUP(AW$1,deflatores_ipca!$B$2:$E$61,4,FALSE) -> 151603.09 | AX6: =CUSTOS_nominal!AX6*VLOOKUP(AX$1,deflatores_ipca!$B$2:$E$61,4,FALSE) -> 58896.585 | ... BN6: =CUSTOS_nominal!BN6*VLOOKUP(BN$1,deflatores_ipca!$B$2:$E$61,4,FALSE) -> 109486.35
A7: IBGE:2701605 | B7: AL | C7: Alagoas | D7: CANAPI | E7: 2701605 | F7: MEDIO | G7: =CUSTOS_nominal!G7*VLOOKUP(G$1,deflatores_ipca!$B$2:$E$61,4,FALSE) -> 114302.99 | H7: =CUSTOS_nominal!H7*VLOOKUP(H$1,deflatores_ipca!$B$2:$E$61,4,FALSE) -> 91786.056 | I7: =CUSTOS_nominal!I7*VLOOKUP(I$1,deflatores_ipca!$B$2:$E$61,4,FALSE) -> 103798.86 | J7: =CUSTOS_nominal!J7*VLOOKUP(J$1,deflatores_ipca!$B$2:$E$61,4,FALSE) -> 101273.44 | K7: =CUSTOS_nominal!K7*VLOOKUP(K$1,deflatores_ipca!$B$2:$E$61,4,FALSE) -> 103182.83 | L7: =CUSTOS_nominal!L7*VLOOKUP(L$1,deflatores_ipca!$B$2:$E$61,4,FALSE) -> 108993.5 | M7: =CUSTOS_nominal!M7*VLOOKUP(M$1,deflatores_ipca!$B$2:$E$61,4,FALSE) -> 107109.36 | N7: =CUSTOS_nominal!N7*VLOOKUP(N$1,deflatores_ipca!$B$2:$E$61,4,FALSE) -> 108735.37 | ... AB7: =CUSTOS_nominal!AB7*VLOOKUP(AB$1,deflatores_ipca!$B$2:$E$61,4,FALSE) -> 134511.69 | AE7: =CUSTOS_nominal!AE7*VLOOKUP(AE$1,deflatores_ipca!$B$2:$E$61,4,FALSE) -> 174640.33 | AF7: =CUSTOS_nominal!AF7*VLOOKUP(AF$1,deflatores_ipca!$B$2:$E$61,4,FALSE) -> 184829.17 | AG7: =CUSTOS_nominal!AG7*VLOOKUP(AG$1,deflatores_ipca!$B$2:$E$61,4,FALSE) -> 229154.74 | AH7: =CUSTOS_nominal!AH7*VLOOKUP(AH$1,deflatores_ipca!$B$2:$E$61,4,FALSE) -> 181505.01 | AI7: =CUSTOS_nominal!AI7*VLOOKUP(AI$1,deflatores_ipca!$B$2:$E$61,4,FALSE) -> 176431.58 | AJ7: =CUSTOS_nominal!AJ7*VLOOKUP(AJ$1,deflatores_ipca!$B$2:$E$61,4,FALSE) -> 79919.87 | AK7: =CUSTOS_nominal!AK7*VLOOKUP(AK$1,deflatores_ipca!$B$2:$E$61,4,FALSE) -> 124665.93 | AL7: =CUSTOS_nominal!AL7*VLOOKUP(AL$1,deflatores_ipca!$B$2:$E$61,4,FALSE) -> 12552.349 | ... AO7: =CUSTOS_nominal!AO7*VLOOKUP(AO$1,deflatores_ipca!$B$2:$E$61,4,FALSE) -> 143282.97 | AQ7: =CUSTOS_nominal!AQ7*VLOOKUP(AQ$1,deflatores_ipca!$B$2:$E$61,4,FALSE) -> 147580.39 | AR7: =CUSTOS_nominal!AR7*VLOOKUP(AR$1,deflatores_ipca!$B$2:$E$61,4,FALSE) -> 133580.47 | AS7: =CUSTOS_nominal!AS7*VLOOKUP(AS$1,deflatores_ipca!$B$2:$E$61,4,FALSE) -> 138922.23 | AT7: =CUSTOS_nominal!AT7*VLOOKUP(AT$1,deflatores_ipca!$B$2:$E$61,4,FALSE) -> 147377.72 | AU7: =CUSTOS_nominal!AU7*VLOOKUP(AU$1,deflatores_ipca!$B$2:$E$61,4,FALSE) -> 144180.73 | AV7: =CUSTOS_nominal!AV7*VLOOKUP(AV$1,deflatores_ipca!$B$2:$E$61,4,FALSE) -> 146517.2 | AW7: =CUSTOS_nominal!AW7*VLOOKUP(AW$1,deflatores_ipca!$B$2:$E$61,4,FALSE) -> 161397.22 | AX7: =CUSTOS_nominal!AX7*VLOOKUP(AX$1,deflatores_ipca!$B$2:$E$61,4,FALSE) -> 115462.38 | ... BN7: =CUSTOS_nominal!BN7*VLOOKUP(BN$1,deflatores_ipca!$B$2:$E$61,4,FALSE) -> 190927.71
A8: IBGE:2701803 | B8: AL | C8: Alagoas | D8: CARNEIROS | E8: 2701803 | F8: MEDIO | G8: =CUSTOS_nominal!G8*VLOOKUP(G$1,deflatores_ipca!$B$2:$E$61,4,FALSE) -> 41910.634 | H8: =CUSTOS_nominal!H8*VLOOKUP(H$1,deflatores_ipca!$B$2:$E$61,4,FALSE) -> 40774.526 | I8: =CUSTOS_nominal!I8*VLOOKUP(I$1,deflatores_ipca!$B$2:$E$61,4,FALSE) -> 44442.271 | J8: =CUSTOS_nominal!J8*VLOOKUP(J$1,deflatores_ipca!$B$2:$E$61,4,FALSE) -> 38954.073 | K8: =CUSTOS_nominal!K8*VLOOKUP(K$1,deflatores_ipca!$B$2:$E$61,4,FALSE) -> 35219.17 | L8: =CUSTOS_nominal!L8*VLOOKUP(L$1,deflatores_ipca!$B$2:$E$61,4,FALSE) -> 42864.146 | M8: =CUSTOS_nominal!M8*VLOOKUP(M$1,deflatores_ipca!$B$2:$E$61,4,FALSE) -> 41173.015 | N8: =CUSTOS_nominal!N8*VLOOKUP(N$1,deflatores_ipca!$B$2:$E$61,4,FALSE) -> 40381.483 | ... AB8: =CUSTOS_nominal!AB8*VLOOKUP(AB$1,deflatores_ipca!$B$2:$E$61,4,FALSE) -> 65125.522 | AE8: =CUSTOS_nominal!AE8*VLOOKUP(AE$1,deflatores_ipca!$B$2:$E$61,4,FALSE) -> 50591.965 | AF8: =CUSTOS_nominal!AF8*VLOOKUP(AF$1,deflatores_ipca!$B$2:$E$61,4,FALSE) -> 58401.322 | AG8: =CUSTOS_nominal!AG8*VLOOKUP(AG$1,deflatores_ipca!$B$2:$E$61,4,FALSE) -> 103873.29 | AH8: =CUSTOS_nominal!AH8*VLOOKUP(AH$1,deflatores_ipca!$B$2:$E$61,4,FALSE) -> 56240.938 | AI8: =CUSTOS_nominal!AI8*VLOOKUP(AI$1,deflatores_ipca!$B$2:$E$61,4,FALSE) -> 56481.541 | AJ8: =CUSTOS_nominal!AJ8*VLOOKUP(AJ$1,deflatores_ipca!$B$2:$E$61,4,FALSE) -> 14278.947 | AK8: =CUSTOS_nominal!AK8*VLOOKUP(AK$1,deflatores_ipca!$B$2:$E$61,4,FALSE) -> 0 | AL8: =CUSTOS_nominal!AL8*VLOOKUP(AL$1,deflatores_ipca!$B$2:$E$61,4,FALSE) -> 17310.903 | ... AO8: =CUSTOS_nominal!AO8*VLOOKUP(AO$1,deflatores_ipca!$B$2:$E$61,4,FALSE) -> 29087.465 | AQ8: =CUSTOS_nominal!AQ8*VLOOKUP(AQ$1,deflatores_ipca!$B$2:$E$61,4,FALSE) -> 31079.529 | AR8: =CUSTOS_nominal!AR8*VLOOKUP(AR$1,deflatores_ipca!$B$2:$E$61,4,FALSE) -> 24446.984 | AS8: =CUSTOS_nominal!AS8*VLOOKUP(AS$1,deflatores_ipca!$B$2:$E$61,4,FALSE) -> 27838.104 | AT8: =CUSTOS_nominal!AT8*VLOOKUP(AT$1,deflatores_ipca!$B$2:$E$61,4,FALSE) -> 29983.667 | AU8: =CUSTOS_nominal!AU8*VLOOKUP(AU$1,deflatores_ipca!$B$2:$E$61,4,FALSE) -> 27579.002 | AV8: =CUSTOS_nominal!AV8*VLOOKUP(AV$1,deflatores_ipca!$B$2:$E$61,4,FALSE) -> 29716.236 | AW8: =CUSTOS_nominal!AW8*VLOOKUP(AW$1,deflatores_ipca!$B$2:$E$61,4,FALSE) -> 32979.344 | AX8: =CUSTOS_nominal!AX8*VLOOKUP(AX$1,deflatores_ipca!$B$2:$E$61,4,FALSE) -> 15089.597 | ... BN8: =CUSTOS_nominal!BN8*VLOOKUP(BN$1,deflatores_ipca!$B$2:$E$61,4,FALSE) -> 39076.97
